[2024-08-11T19:58:02.078+0000] {local_task_job_runner.py:120} INFO - ::group::Pre task execution logs
[2024-08-11T19:58:02.088+0000] {taskinstance.py:2076} INFO - Dependencies all met for dep_context=non-requeueable deps ti=<TaskInstance: weather.import_weather_data_to_csv manual__2024-08-11T19:47:54.506018+00:00 [queued]>
[2024-08-11T19:58:02.091+0000] {taskinstance.py:2076} INFO - Dependencies all met for dep_context=requeueable deps ti=<TaskInstance: weather.import_weather_data_to_csv manual__2024-08-11T19:47:54.506018+00:00 [queued]>
[2024-08-11T19:58:02.091+0000] {taskinstance.py:2306} INFO - Starting attempt 2 of 2
[2024-08-11T19:58:02.095+0000] {taskinstance.py:2330} INFO - Executing <Task(BashOperator): import_weather_data_to_csv> on 2024-08-11 19:47:54.506018+00:00
[2024-08-11T19:58:02.099+0000] {warnings.py:112} WARNING - /home/***/.local/lib/python3.12/site-packages/***/task/task_runner/standard_task_runner.py:62: DeprecationWarning: This process (pid=219) is multi-threaded, use of fork() may lead to deadlocks in the child.
  pid = os.fork()

[2024-08-11T19:58:02.100+0000] {standard_task_runner.py:64} INFO - Started process 221 to run task
[2024-08-11T19:58:02.100+0000] {standard_task_runner.py:90} INFO - Running: ['***', 'tasks', 'run', 'weather', 'import_weather_data_to_csv', 'manual__2024-08-11T19:47:54.506018+00:00', '--job-id', '45', '--raw', '--subdir', 'DAGS_FOLDER/weather_dag.py', '--cfg-path', '/tmp/tmpryo9wcqo']
[2024-08-11T19:58:02.101+0000] {standard_task_runner.py:91} INFO - Job 45: Subtask import_weather_data_to_csv
[2024-08-11T19:58:02.122+0000] {task_command.py:426} INFO - Running <TaskInstance: weather.import_weather_data_to_csv manual__2024-08-11T19:47:54.506018+00:00 [running]> on host 0a7d98c62b27
[2024-08-11T19:58:02.152+0000] {taskinstance.py:2648} INFO - Exporting env vars: AIRFLOW_CTX_DAG_OWNER='***' AIRFLOW_CTX_DAG_ID='weather' AIRFLOW_CTX_TASK_ID='import_weather_data_to_csv' AIRFLOW_CTX_EXECUTION_DATE='2024-08-11T19:47:54.506018+00:00' AIRFLOW_CTX_TRY_NUMBER='2' AIRFLOW_CTX_DAG_RUN_ID='manual__2024-08-11T19:47:54.506018+00:00'
[2024-08-11T19:58:02.153+0000] {taskinstance.py:430} INFO - ::endgroup::
[2024-08-11T19:58:02.153+0000] {subprocess.py:63} INFO - Tmp dir root location: /tmp
[2024-08-11T19:58:02.154+0000] {subprocess.py:75} INFO - Running command: ['/usr/bin/bash', '-c', 'python /opt/***/dags/weather_data_ingestion.py --date 2024-08-11']
[2024-08-11T19:58:02.158+0000] {subprocess.py:86} INFO - Output:
[2024-08-11T19:58:02.451+0000] {subprocess.py:93} INFO - Traceback (most recent call last):
[2024-08-11T19:58:02.460+0000] {subprocess.py:93} INFO -   File "/opt/***/dags/weather_data_ingestion.py", line 2, in <module>
[2024-08-11T19:58:02.462+0000] {subprocess.py:93} INFO -     import openmeteo_requests
[2024-08-11T19:58:02.462+0000] {subprocess.py:93} INFO - ModuleNotFoundError: No module named 'openmeteo_requests'
[2024-08-11T19:58:02.464+0000] {subprocess.py:97} INFO - Command exited with return code 1
[2024-08-11T19:58:02.464+0000] {taskinstance.py:441} INFO - ::group::Post task execution logs
[2024-08-11T19:58:02.470+0000] {taskinstance.py:2905} ERROR - Task failed with exception
Traceback (most recent call last):
  File "/home/airflow/.local/lib/python3.12/site-packages/airflow/models/taskinstance.py", line 465, in _execute_task
    result = _execute_callable(context=context, **execute_callable_kwargs)
             ^^^^^^^^^^^^^^^^^^^^^^^^^^^^^^^^^^^^^^^^^^^^^^^^^^^^^^^^^^^^^
  File "/home/airflow/.local/lib/python3.12/site-packages/airflow/models/taskinstance.py", line 432, in _execute_callable
    return execute_callable(context=context, **execute_callable_kwargs)
           ^^^^^^^^^^^^^^^^^^^^^^^^^^^^^^^^^^^^^^^^^^^^^^^^^^^^^^^^^^^^
  File "/home/airflow/.local/lib/python3.12/site-packages/airflow/models/baseoperator.py", line 401, in wrapper
    return func(self, *args, **kwargs)
           ^^^^^^^^^^^^^^^^^^^^^^^^^^^
  File "/home/airflow/.local/lib/python3.12/site-packages/airflow/operators/bash.py", line 243, in execute
    raise AirflowException(
airflow.exceptions.AirflowException: Bash command failed. The command returned a non-zero exit code 1.
[2024-08-11T19:58:02.473+0000] {taskinstance.py:1206} INFO - Marking task as FAILED. dag_id=weather, task_id=import_weather_data_to_csv, run_id=manual__2024-08-11T19:47:54.506018+00:00, execution_date=20240811T194754, start_date=20240811T195802, end_date=20240811T195802
[2024-08-11T19:58:02.479+0000] {standard_task_runner.py:110} ERROR - Failed to execute job 45 for task import_weather_data_to_csv (Bash command failed. The command returned a non-zero exit code 1.; 221)
[2024-08-11T19:58:02.491+0000] {local_task_job_runner.py:243} INFO - Task exited with return code 1
[2024-08-11T19:58:02.500+0000] {taskinstance.py:3503} INFO - 0 downstream tasks scheduled from follow-on schedule check
[2024-08-11T19:58:02.502+0000] {local_task_job_runner.py:222} INFO - ::endgroup::
