[2024-08-11T05:20:40.499+0000] {local_task_job_runner.py:120} INFO - ::group::Pre task execution logs
[2024-08-11T05:20:40.511+0000] {taskinstance.py:2076} INFO - Dependencies all met for dep_context=non-requeueable deps ti=<TaskInstance: weather_data_migration.weather_data_migration manual__2024-08-11T05:20:39.172044+00:00 [queued]>
[2024-08-11T05:20:40.514+0000] {taskinstance.py:2076} INFO - Dependencies all met for dep_context=requeueable deps ti=<TaskInstance: weather_data_migration.weather_data_migration manual__2024-08-11T05:20:39.172044+00:00 [queued]>
[2024-08-11T05:20:40.515+0000] {taskinstance.py:2306} INFO - Starting attempt 1 of 2
[2024-08-11T05:20:40.520+0000] {taskinstance.py:2330} INFO - Executing <Task(BashOperator): weather_data_migration> on 2024-08-11 05:20:39.172044+00:00
[2024-08-11T05:20:40.538+0000] {warnings.py:112} WARNING - /home/***/.local/lib/python3.12/site-packages/***/task/task_runner/standard_task_runner.py:62: DeprecationWarning: This process (pid=2689) is multi-threaded, use of fork() may lead to deadlocks in the child.
  pid = os.fork()

[2024-08-11T05:20:40.539+0000] {standard_task_runner.py:64} INFO - Started process 2691 to run task
[2024-08-11T05:20:40.539+0000] {standard_task_runner.py:90} INFO - Running: ['***', 'tasks', 'run', 'weather_data_migration', 'weather_data_migration', 'manual__2024-08-11T05:20:39.172044+00:00', '--job-id', '11', '--raw', '--subdir', 'DAGS_FOLDER/weather_data_migration_dag.py', '--cfg-path', '/tmp/tmpwl3av2s2']
[2024-08-11T05:20:40.542+0000] {standard_task_runner.py:91} INFO - Job 11: Subtask weather_data_migration
[2024-08-11T05:20:40.566+0000] {task_command.py:426} INFO - Running <TaskInstance: weather_data_migration.weather_data_migration manual__2024-08-11T05:20:39.172044+00:00 [running]> on host a904838c11ba
[2024-08-11T05:20:40.608+0000] {taskinstance.py:2648} INFO - Exporting env vars: AIRFLOW_CTX_DAG_OWNER='***' AIRFLOW_CTX_DAG_ID='weather_data_migration' AIRFLOW_CTX_TASK_ID='weather_data_migration' AIRFLOW_CTX_EXECUTION_DATE='2024-08-11T05:20:39.172044+00:00' AIRFLOW_CTX_TRY_NUMBER='1' AIRFLOW_CTX_DAG_RUN_ID='manual__2024-08-11T05:20:39.172044+00:00'
[2024-08-11T05:20:40.610+0000] {taskinstance.py:430} INFO - ::endgroup::
[2024-08-11T05:20:40.611+0000] {subprocess.py:63} INFO - Tmp dir root location: /tmp
[2024-08-11T05:20:40.611+0000] {subprocess.py:75} INFO - Running command: ['/usr/bin/bash', '-c', 'python /opt/***/dags/weather_data_migration.py --connection postgresql+psycopg2://***:***@postgres/***']
[2024-08-11T05:20:40.616+0000] {subprocess.py:86} INFO - Output:
[2024-08-11T05:20:41.767+0000] {subprocess.py:93} INFO - Traceback (most recent call last):
[2024-08-11T05:20:41.769+0000] {subprocess.py:93} INFO -   File "/opt/***/dags/weather_data_migration.py", line 39, in <module>
[2024-08-11T05:20:41.769+0000] {subprocess.py:93} INFO -     main(args.connection)
[2024-08-11T05:20:41.770+0000] {subprocess.py:93} INFO -   File "/opt/***/dags/weather_data_migration.py", line 12, in main
[2024-08-11T05:20:41.770+0000] {subprocess.py:93} INFO -     session = connection.get_session()
[2024-08-11T05:20:41.770+0000] {subprocess.py:93} INFO -               ^^^^^^^^^^^^^^^^^^^^^^
[2024-08-11T05:20:41.770+0000] {subprocess.py:93} INFO - AttributeError: 'Connection' object has no attribute 'get_session'
[2024-08-11T05:20:41.888+0000] {subprocess.py:97} INFO - Command exited with return code 1
[2024-08-11T05:20:41.890+0000] {taskinstance.py:441} INFO - ::group::Post task execution logs
[2024-08-11T05:20:41.901+0000] {taskinstance.py:2905} ERROR - Task failed with exception
Traceback (most recent call last):
  File "/home/airflow/.local/lib/python3.12/site-packages/airflow/models/taskinstance.py", line 465, in _execute_task
    result = _execute_callable(context=context, **execute_callable_kwargs)
             ^^^^^^^^^^^^^^^^^^^^^^^^^^^^^^^^^^^^^^^^^^^^^^^^^^^^^^^^^^^^^
  File "/home/airflow/.local/lib/python3.12/site-packages/airflow/models/taskinstance.py", line 432, in _execute_callable
    return execute_callable(context=context, **execute_callable_kwargs)
           ^^^^^^^^^^^^^^^^^^^^^^^^^^^^^^^^^^^^^^^^^^^^^^^^^^^^^^^^^^^^
  File "/home/airflow/.local/lib/python3.12/site-packages/airflow/models/baseoperator.py", line 401, in wrapper
    return func(self, *args, **kwargs)
           ^^^^^^^^^^^^^^^^^^^^^^^^^^^
  File "/home/airflow/.local/lib/python3.12/site-packages/airflow/operators/bash.py", line 243, in execute
    raise AirflowException(
airflow.exceptions.AirflowException: Bash command failed. The command returned a non-zero exit code 1.
[2024-08-11T05:20:41.907+0000] {taskinstance.py:1206} INFO - Marking task as UP_FOR_RETRY. dag_id=weather_data_migration, task_id=weather_data_migration, run_id=manual__2024-08-11T05:20:39.172044+00:00, execution_date=20240811T052039, start_date=20240811T052040, end_date=20240811T052041
[2024-08-11T05:20:41.914+0000] {standard_task_runner.py:110} ERROR - Failed to execute job 11 for task weather_data_migration (Bash command failed. The command returned a non-zero exit code 1.; 2691)
[2024-08-11T05:20:41.940+0000] {local_task_job_runner.py:243} INFO - Task exited with return code 1
[2024-08-11T05:20:41.963+0000] {taskinstance.py:3503} INFO - 0 downstream tasks scheduled from follow-on schedule check
[2024-08-11T05:20:41.964+0000] {local_task_job_runner.py:222} INFO - ::endgroup::
