[2024-08-11T05:38:56.645+0000] {local_task_job_runner.py:120} INFO - ::group::Pre task execution logs
[2024-08-11T05:38:56.683+0000] {taskinstance.py:2076} INFO - Dependencies all met for dep_context=non-requeueable deps ti=<TaskInstance: weather.import_weather_data_to_csv scheduled__2024-08-10T00:00:00+00:00 [queued]>
[2024-08-11T05:38:56.688+0000] {taskinstance.py:2076} INFO - Dependencies all met for dep_context=requeueable deps ti=<TaskInstance: weather.import_weather_data_to_csv scheduled__2024-08-10T00:00:00+00:00 [queued]>
[2024-08-11T05:38:56.689+0000] {taskinstance.py:2306} INFO - Starting attempt 2 of 2
[2024-08-11T05:38:56.697+0000] {taskinstance.py:2330} INFO - Executing <Task(BashOperator): import_weather_data_to_csv> on 2024-08-10 00:00:00+00:00
[2024-08-11T05:38:56.723+0000] {warnings.py:112} WARNING - /home/***/.local/lib/python3.12/site-packages/***/task/task_runner/standard_task_runner.py:62: DeprecationWarning: This process (pid=2980) is multi-threaded, use of fork() may lead to deadlocks in the child.
  pid = os.fork()

[2024-08-11T05:38:56.730+0000] {standard_task_runner.py:64} INFO - Started process 2990 to run task
[2024-08-11T05:38:56.731+0000] {standard_task_runner.py:90} INFO - Running: ['***', 'tasks', 'run', 'weather', 'import_weather_data_to_csv', 'scheduled__2024-08-10T00:00:00+00:00', '--job-id', '25', '--raw', '--subdir', 'DAGS_FOLDER/weather_dag.py', '--cfg-path', '/tmp/tmpotyevzc8']
[2024-08-11T05:38:56.742+0000] {standard_task_runner.py:91} INFO - Job 25: Subtask import_weather_data_to_csv
[2024-08-11T05:38:56.862+0000] {task_command.py:426} INFO - Running <TaskInstance: weather.import_weather_data_to_csv scheduled__2024-08-10T00:00:00+00:00 [running]> on host a904838c11ba
[2024-08-11T05:38:57.114+0000] {taskinstance.py:2648} INFO - Exporting env vars: AIRFLOW_CTX_DAG_OWNER='***' AIRFLOW_CTX_DAG_ID='weather' AIRFLOW_CTX_TASK_ID='import_weather_data_to_csv' AIRFLOW_CTX_EXECUTION_DATE='2024-08-10T00:00:00+00:00' AIRFLOW_CTX_TRY_NUMBER='2' AIRFLOW_CTX_DAG_RUN_ID='scheduled__2024-08-10T00:00:00+00:00'
[2024-08-11T05:38:57.138+0000] {taskinstance.py:430} INFO - ::endgroup::
[2024-08-11T05:38:57.173+0000] {subprocess.py:63} INFO - Tmp dir root location: /tmp
[2024-08-11T05:38:57.176+0000] {subprocess.py:75} INFO - Running command: ['/usr/bin/bash', '-c', 'python /opt/***/dags/weather_data_ingestion.py --date 2024-08-10']
[2024-08-11T05:38:57.214+0000] {subprocess.py:86} INFO - Output:
[2024-08-11T05:38:59.246+0000] {subprocess.py:93} INFO - Traceback (most recent call last):
[2024-08-11T05:38:59.254+0000] {subprocess.py:93} INFO -   File "/opt/***/dags/weather_data_ingestion.py", line 2, in <module>
[2024-08-11T05:38:59.257+0000] {subprocess.py:93} INFO -     import openmeteo_requests
[2024-08-11T05:38:59.257+0000] {subprocess.py:93} INFO - ModuleNotFoundError: No module named 'openmeteo_requests'
[2024-08-11T05:38:59.298+0000] {subprocess.py:97} INFO - Command exited with return code 1
[2024-08-11T05:38:59.303+0000] {taskinstance.py:441} INFO - ::group::Post task execution logs
[2024-08-11T05:38:59.391+0000] {taskinstance.py:2905} ERROR - Task failed with exception
Traceback (most recent call last):
  File "/home/airflow/.local/lib/python3.12/site-packages/airflow/models/taskinstance.py", line 465, in _execute_task
    result = _execute_callable(context=context, **execute_callable_kwargs)
             ^^^^^^^^^^^^^^^^^^^^^^^^^^^^^^^^^^^^^^^^^^^^^^^^^^^^^^^^^^^^^
  File "/home/airflow/.local/lib/python3.12/site-packages/airflow/models/taskinstance.py", line 432, in _execute_callable
    return execute_callable(context=context, **execute_callable_kwargs)
           ^^^^^^^^^^^^^^^^^^^^^^^^^^^^^^^^^^^^^^^^^^^^^^^^^^^^^^^^^^^^
  File "/home/airflow/.local/lib/python3.12/site-packages/airflow/models/baseoperator.py", line 401, in wrapper
    return func(self, *args, **kwargs)
           ^^^^^^^^^^^^^^^^^^^^^^^^^^^
  File "/home/airflow/.local/lib/python3.12/site-packages/airflow/operators/bash.py", line 243, in execute
    raise AirflowException(
airflow.exceptions.AirflowException: Bash command failed. The command returned a non-zero exit code 1.
[2024-08-11T05:38:59.430+0000] {taskinstance.py:1206} INFO - Marking task as FAILED. dag_id=weather, task_id=import_weather_data_to_csv, run_id=scheduled__2024-08-10T00:00:00+00:00, execution_date=20240810T000000, start_date=20240811T053856, end_date=20240811T053859
[2024-08-11T05:38:59.472+0000] {standard_task_runner.py:110} ERROR - Failed to execute job 25 for task import_weather_data_to_csv (Bash command failed. The command returned a non-zero exit code 1.; 2990)
[2024-08-11T05:38:59.526+0000] {local_task_job_runner.py:243} INFO - Task exited with return code 1
[2024-08-11T05:38:59.570+0000] {local_task_job_runner.py:222} INFO - ::endgroup::
