[2024-08-11T05:33:50.520+0000] {local_task_job_runner.py:120} INFO - ::group::Pre task execution logs
[2024-08-11T05:33:51.051+0000] {taskinstance.py:2076} INFO - Dependencies all met for dep_context=non-requeueable deps ti=<TaskInstance: weather.import_weather_data_to_csv scheduled__2024-08-09T00:00:00+00:00 [queued]>
[2024-08-11T05:33:51.098+0000] {taskinstance.py:2076} INFO - Dependencies all met for dep_context=requeueable deps ti=<TaskInstance: weather.import_weather_data_to_csv scheduled__2024-08-09T00:00:00+00:00 [queued]>
[2024-08-11T05:33:51.101+0000] {taskinstance.py:2306} INFO - Starting attempt 1 of 2
[2024-08-11T05:33:51.181+0000] {taskinstance.py:2330} INFO - Executing <Task(BashOperator): import_weather_data_to_csv> on 2024-08-09 00:00:00+00:00
[2024-08-11T05:33:51.235+0000] {warnings.py:112} WARNING - /home/***/.local/lib/python3.12/site-packages/***/task/task_runner/standard_task_runner.py:62: DeprecationWarning: This process (pid=2883) is multi-threaded, use of fork() may lead to deadlocks in the child.
  pid = os.fork()

[2024-08-11T05:33:51.242+0000] {standard_task_runner.py:64} INFO - Started process 2902 to run task
[2024-08-11T05:33:51.246+0000] {standard_task_runner.py:90} INFO - Running: ['***', 'tasks', 'run', 'weather', 'import_weather_data_to_csv', 'scheduled__2024-08-09T00:00:00+00:00', '--job-id', '18', '--raw', '--subdir', 'DAGS_FOLDER/weather_dag.py', '--cfg-path', '/tmp/tmpf6_oa6fe']
[2024-08-11T05:33:51.277+0000] {standard_task_runner.py:91} INFO - Job 18: Subtask import_weather_data_to_csv
[2024-08-11T05:33:51.589+0000] {task_command.py:426} INFO - Running <TaskInstance: weather.import_weather_data_to_csv scheduled__2024-08-09T00:00:00+00:00 [running]> on host a904838c11ba
[2024-08-11T05:33:51.844+0000] {taskinstance.py:2648} INFO - Exporting env vars: AIRFLOW_CTX_DAG_OWNER='***' AIRFLOW_CTX_DAG_ID='weather' AIRFLOW_CTX_TASK_ID='import_weather_data_to_csv' AIRFLOW_CTX_EXECUTION_DATE='2024-08-09T00:00:00+00:00' AIRFLOW_CTX_TRY_NUMBER='1' AIRFLOW_CTX_DAG_RUN_ID='scheduled__2024-08-09T00:00:00+00:00'
[2024-08-11T05:33:51.873+0000] {taskinstance.py:430} INFO - ::endgroup::
[2024-08-11T05:33:51.889+0000] {subprocess.py:63} INFO - Tmp dir root location: /tmp
[2024-08-11T05:33:51.892+0000] {subprocess.py:75} INFO - Running command: ['/usr/bin/bash', '-c', 'python /opt/***/dags/weather_data_ingestion.py --date 2024-08-09']
[2024-08-11T05:33:52.006+0000] {subprocess.py:86} INFO - Output:
[2024-08-11T05:33:54.154+0000] {subprocess.py:93} INFO - Traceback (most recent call last):
[2024-08-11T05:33:54.226+0000] {subprocess.py:93} INFO -   File "/opt/***/dags/weather_data_ingestion.py", line 2, in <module>
[2024-08-11T05:33:54.239+0000] {subprocess.py:93} INFO -     import openmeteo_requests
[2024-08-11T05:33:54.241+0000] {subprocess.py:93} INFO - ModuleNotFoundError: No module named 'openmeteo_requests'
[2024-08-11T05:33:54.313+0000] {subprocess.py:97} INFO - Command exited with return code 1
[2024-08-11T05:33:54.324+0000] {taskinstance.py:441} INFO - ::group::Post task execution logs
[2024-08-11T05:33:54.419+0000] {taskinstance.py:2905} ERROR - Task failed with exception
Traceback (most recent call last):
  File "/home/airflow/.local/lib/python3.12/site-packages/airflow/models/taskinstance.py", line 465, in _execute_task
    result = _execute_callable(context=context, **execute_callable_kwargs)
             ^^^^^^^^^^^^^^^^^^^^^^^^^^^^^^^^^^^^^^^^^^^^^^^^^^^^^^^^^^^^^
  File "/home/airflow/.local/lib/python3.12/site-packages/airflow/models/taskinstance.py", line 432, in _execute_callable
    return execute_callable(context=context, **execute_callable_kwargs)
           ^^^^^^^^^^^^^^^^^^^^^^^^^^^^^^^^^^^^^^^^^^^^^^^^^^^^^^^^^^^^
  File "/home/airflow/.local/lib/python3.12/site-packages/airflow/models/baseoperator.py", line 401, in wrapper
    return func(self, *args, **kwargs)
           ^^^^^^^^^^^^^^^^^^^^^^^^^^^
  File "/home/airflow/.local/lib/python3.12/site-packages/airflow/operators/bash.py", line 243, in execute
    raise AirflowException(
airflow.exceptions.AirflowException: Bash command failed. The command returned a non-zero exit code 1.
[2024-08-11T05:33:54.481+0000] {taskinstance.py:1206} INFO - Marking task as UP_FOR_RETRY. dag_id=weather, task_id=import_weather_data_to_csv, run_id=scheduled__2024-08-09T00:00:00+00:00, execution_date=20240809T000000, start_date=20240811T053351, end_date=20240811T053354
[2024-08-11T05:33:54.532+0000] {standard_task_runner.py:110} ERROR - Failed to execute job 18 for task import_weather_data_to_csv (Bash command failed. The command returned a non-zero exit code 1.; 2902)
[2024-08-11T05:33:54.614+0000] {local_task_job_runner.py:243} INFO - Task exited with return code 1
[2024-08-11T05:33:54.763+0000] {taskinstance.py:3503} INFO - 0 downstream tasks scheduled from follow-on schedule check
[2024-08-11T05:33:54.768+0000] {local_task_job_runner.py:222} INFO - ::endgroup::
