[2024-08-11T05:05:32.031+0000] {local_task_job_runner.py:120} INFO - ::group::Pre task execution logs
[2024-08-11T05:05:32.071+0000] {taskinstance.py:2076} INFO - Dependencies all met for dep_context=non-requeueable deps ti=<TaskInstance: weather_data_migration.weather_data_migration scheduled__2024-08-11T00:00:00+00:00 [queued]>
[2024-08-11T05:05:32.090+0000] {taskinstance.py:2076} INFO - Dependencies all met for dep_context=requeueable deps ti=<TaskInstance: weather_data_migration.weather_data_migration scheduled__2024-08-11T00:00:00+00:00 [queued]>
[2024-08-11T05:05:32.091+0000] {taskinstance.py:2306} INFO - Starting attempt 1 of 2
[2024-08-11T05:05:32.121+0000] {taskinstance.py:2330} INFO - Executing <Task(BashOperator): weather_data_migration> on 2024-08-11 00:00:00+00:00
[2024-08-11T05:05:32.142+0000] {warnings.py:112} WARNING - /home/***/.local/lib/python3.12/site-packages/***/task/task_runner/standard_task_runner.py:62: DeprecationWarning: This process (pid=2464) is multi-threaded, use of fork() may lead to deadlocks in the child.
  pid = os.fork()

[2024-08-11T05:05:32.153+0000] {standard_task_runner.py:64} INFO - Started process 2468 to run task
[2024-08-11T05:05:32.153+0000] {standard_task_runner.py:90} INFO - Running: ['***', 'tasks', 'run', 'weather_data_migration', 'weather_data_migration', 'scheduled__2024-08-11T00:00:00+00:00', '--job-id', '5', '--raw', '--subdir', 'DAGS_FOLDER/weather_data_migration_dag.py', '--cfg-path', '/tmp/tmpwuoowdhv']
[2024-08-11T05:05:32.172+0000] {standard_task_runner.py:91} INFO - Job 5: Subtask weather_data_migration
[2024-08-11T05:05:32.322+0000] {task_command.py:426} INFO - Running <TaskInstance: weather_data_migration.weather_data_migration scheduled__2024-08-11T00:00:00+00:00 [running]> on host a904838c11ba
[2024-08-11T05:05:32.509+0000] {taskinstance.py:2648} INFO - Exporting env vars: AIRFLOW_CTX_DAG_OWNER='***' AIRFLOW_CTX_DAG_ID='weather_data_migration' AIRFLOW_CTX_TASK_ID='weather_data_migration' AIRFLOW_CTX_EXECUTION_DATE='2024-08-11T00:00:00+00:00' AIRFLOW_CTX_TRY_NUMBER='1' AIRFLOW_CTX_DAG_RUN_ID='scheduled__2024-08-11T00:00:00+00:00'
[2024-08-11T05:05:32.533+0000] {taskinstance.py:430} INFO - ::endgroup::
[2024-08-11T05:05:32.537+0000] {subprocess.py:63} INFO - Tmp dir root location: /tmp
[2024-08-11T05:05:32.539+0000] {subprocess.py:75} INFO - Running command: ['/usr/bin/bash', '-c', 'python /opt/***/dags/weather_data_migration.py --connection postgresql+psycopg2://***:***@postgres/***']
[2024-08-11T05:05:32.571+0000] {subprocess.py:86} INFO - Output:
[2024-08-11T05:05:36.738+0000] {subprocess.py:93} INFO - Traceback (most recent call last):
[2024-08-11T05:05:36.760+0000] {subprocess.py:93} INFO -   File "/opt/***/dags/weather_data_migration.py", line 39, in <module>
[2024-08-11T05:05:36.765+0000] {subprocess.py:93} INFO -     main(args.connection)
[2024-08-11T05:05:36.767+0000] {subprocess.py:93} INFO -   File "/opt/***/dags/weather_data_migration.py", line 12, in main
[2024-08-11T05:05:36.768+0000] {subprocess.py:93} INFO -     session = connection.get_session()
[2024-08-11T05:05:36.769+0000] {subprocess.py:93} INFO -               ^^^^^^^^^^^^^^^^^^^^^^
[2024-08-11T05:05:36.770+0000] {subprocess.py:93} INFO - AttributeError: 'Connection' object has no attribute 'get_session'
[2024-08-11T05:05:37.063+0000] {subprocess.py:97} INFO - Command exited with return code 1
[2024-08-11T05:05:37.070+0000] {taskinstance.py:441} INFO - ::group::Post task execution logs
[2024-08-11T05:05:37.147+0000] {taskinstance.py:2905} ERROR - Task failed with exception
Traceback (most recent call last):
  File "/home/airflow/.local/lib/python3.12/site-packages/airflow/models/taskinstance.py", line 465, in _execute_task
    result = _execute_callable(context=context, **execute_callable_kwargs)
             ^^^^^^^^^^^^^^^^^^^^^^^^^^^^^^^^^^^^^^^^^^^^^^^^^^^^^^^^^^^^^
  File "/home/airflow/.local/lib/python3.12/site-packages/airflow/models/taskinstance.py", line 432, in _execute_callable
    return execute_callable(context=context, **execute_callable_kwargs)
           ^^^^^^^^^^^^^^^^^^^^^^^^^^^^^^^^^^^^^^^^^^^^^^^^^^^^^^^^^^^^
  File "/home/airflow/.local/lib/python3.12/site-packages/airflow/models/baseoperator.py", line 401, in wrapper
    return func(self, *args, **kwargs)
           ^^^^^^^^^^^^^^^^^^^^^^^^^^^
  File "/home/airflow/.local/lib/python3.12/site-packages/airflow/operators/bash.py", line 243, in execute
    raise AirflowException(
airflow.exceptions.AirflowException: Bash command failed. The command returned a non-zero exit code 1.
[2024-08-11T05:05:37.171+0000] {taskinstance.py:1206} INFO - Marking task as UP_FOR_RETRY. dag_id=weather_data_migration, task_id=weather_data_migration, run_id=scheduled__2024-08-11T00:00:00+00:00, execution_date=20240811T000000, start_date=20240811T050532, end_date=20240811T050537
[2024-08-11T05:05:37.203+0000] {standard_task_runner.py:110} ERROR - Failed to execute job 5 for task weather_data_migration (Bash command failed. The command returned a non-zero exit code 1.; 2468)
[2024-08-11T05:05:37.294+0000] {local_task_job_runner.py:243} INFO - Task exited with return code 1
[2024-08-11T05:05:37.322+0000] {taskinstance.py:3503} INFO - 0 downstream tasks scheduled from follow-on schedule check
[2024-08-11T05:05:37.324+0000] {local_task_job_runner.py:222} INFO - ::endgroup::
