[2024-08-11T05:27:59.718+0000] {local_task_job_runner.py:120} INFO - ::group::Pre task execution logs
[2024-08-11T05:27:59.729+0000] {taskinstance.py:2076} INFO - Dependencies all met for dep_context=non-requeueable deps ti=<TaskInstance: weather_data_migration.weather_data_migration manual__2024-08-11T05:27:57.613781+00:00 [queued]>
[2024-08-11T05:27:59.732+0000] {taskinstance.py:2076} INFO - Dependencies all met for dep_context=requeueable deps ti=<TaskInstance: weather_data_migration.weather_data_migration manual__2024-08-11T05:27:57.613781+00:00 [queued]>
[2024-08-11T05:27:59.732+0000] {taskinstance.py:2306} INFO - Starting attempt 1 of 2
[2024-08-11T05:27:59.737+0000] {taskinstance.py:2330} INFO - Executing <Task(BashOperator): weather_data_migration> on 2024-08-11 05:27:57.613781+00:00
[2024-08-11T05:27:59.750+0000] {warnings.py:112} WARNING - /home/***/.local/lib/python3.12/site-packages/***/task/task_runner/standard_task_runner.py:62: DeprecationWarning: This process (pid=2793) is multi-threaded, use of fork() may lead to deadlocks in the child.
  pid = os.fork()

[2024-08-11T05:27:59.753+0000] {standard_task_runner.py:64} INFO - Started process 2795 to run task
[2024-08-11T05:27:59.754+0000] {standard_task_runner.py:90} INFO - Running: ['***', 'tasks', 'run', 'weather_data_migration', 'weather_data_migration', 'manual__2024-08-11T05:27:57.613781+00:00', '--job-id', '13', '--raw', '--subdir', 'DAGS_FOLDER/weather_data_migration_dag.py', '--cfg-path', '/tmp/tmpc10mcbsv']
[2024-08-11T05:27:59.760+0000] {standard_task_runner.py:91} INFO - Job 13: Subtask weather_data_migration
[2024-08-11T05:27:59.815+0000] {task_command.py:426} INFO - Running <TaskInstance: weather_data_migration.weather_data_migration manual__2024-08-11T05:27:57.613781+00:00 [running]> on host a904838c11ba
[2024-08-11T05:27:59.885+0000] {taskinstance.py:2648} INFO - Exporting env vars: AIRFLOW_CTX_DAG_OWNER='***' AIRFLOW_CTX_DAG_ID='weather_data_migration' AIRFLOW_CTX_TASK_ID='weather_data_migration' AIRFLOW_CTX_EXECUTION_DATE='2024-08-11T05:27:57.613781+00:00' AIRFLOW_CTX_TRY_NUMBER='1' AIRFLOW_CTX_DAG_RUN_ID='manual__2024-08-11T05:27:57.613781+00:00'
[2024-08-11T05:27:59.890+0000] {taskinstance.py:430} INFO - ::endgroup::
[2024-08-11T05:27:59.891+0000] {subprocess.py:63} INFO - Tmp dir root location: /tmp
[2024-08-11T05:27:59.892+0000] {subprocess.py:75} INFO - Running command: ['/usr/bin/bash', '-c', 'python /opt/***/dags/weather_data_migration.py --connection postgresql+psycopg2://***:***@postgres/***']
[2024-08-11T05:27:59.901+0000] {subprocess.py:86} INFO - Output:
[2024-08-11T05:28:00.630+0000] {subprocess.py:93} INFO - Traceback (most recent call last):
[2024-08-11T05:28:00.633+0000] {subprocess.py:93} INFO -   File "/home/***/.local/lib/python3.12/site-packages/sqlalchemy/engine/base.py", line 1910, in _execute_context
[2024-08-11T05:28:00.633+0000] {subprocess.py:93} INFO -     self.dialect.do_execute(
[2024-08-11T05:28:00.634+0000] {subprocess.py:93} INFO -   File "/home/***/.local/lib/python3.12/site-packages/sqlalchemy/engine/default.py", line 736, in do_execute
[2024-08-11T05:28:00.634+0000] {subprocess.py:93} INFO -     cursor.execute(statement, parameters)
[2024-08-11T05:28:00.634+0000] {subprocess.py:93} INFO - psycopg2.errors.SyntaxError: syntax error at or near "date"
[2024-08-11T05:28:00.635+0000] {subprocess.py:93} INFO - LINE 3:     date TIMESTAMP,
[2024-08-11T05:28:00.635+0000] {subprocess.py:93} INFO -             ^
[2024-08-11T05:28:00.635+0000] {subprocess.py:93} INFO - 
[2024-08-11T05:28:00.635+0000] {subprocess.py:93} INFO - 
[2024-08-11T05:28:00.636+0000] {subprocess.py:93} INFO - The above exception was the direct cause of the following exception:
[2024-08-11T05:28:00.636+0000] {subprocess.py:93} INFO - 
[2024-08-11T05:28:00.636+0000] {subprocess.py:93} INFO - Traceback (most recent call last):
[2024-08-11T05:28:00.637+0000] {subprocess.py:93} INFO -   File "/opt/***/dags/weather_data_migration.py", line 39, in <module>
[2024-08-11T05:28:00.637+0000] {subprocess.py:93} INFO -     main(args.connection)
[2024-08-11T05:28:00.637+0000] {subprocess.py:93} INFO -   File "/opt/***/dags/weather_data_migration.py", line 13, in main
[2024-08-11T05:28:00.638+0000] {subprocess.py:93} INFO -     session.execute('''CREATE TABLE IF NOT EXISTS openmeteo (
[2024-08-11T05:28:00.638+0000] {subprocess.py:93} INFO -   File "/home/***/.local/lib/python3.12/site-packages/sqlalchemy/orm/session.py", line 1717, in execute
[2024-08-11T05:28:00.638+0000] {subprocess.py:93} INFO -     result = conn._execute_20(statement, params or {}, execution_options)
[2024-08-11T05:28:00.638+0000] {subprocess.py:93} INFO -              ^^^^^^^^^^^^^^^^^^^^^^^^^^^^^^^^^^^^^^^^^^^^^^^^^^^^^^^^^^^^
[2024-08-11T05:28:00.639+0000] {subprocess.py:93} INFO -   File "/home/***/.local/lib/python3.12/site-packages/sqlalchemy/engine/base.py", line 1710, in _execute_20
[2024-08-11T05:28:00.639+0000] {subprocess.py:93} INFO -     return meth(self, args_10style, kwargs_10style, execution_options)
[2024-08-11T05:28:00.639+0000] {subprocess.py:93} INFO -            ^^^^^^^^^^^^^^^^^^^^^^^^^^^^^^^^^^^^^^^^^^^^^^^^^^^^^^^^^^^
[2024-08-11T05:28:00.639+0000] {subprocess.py:93} INFO -   File "/home/***/.local/lib/python3.12/site-packages/sqlalchemy/sql/elements.py", line 334, in _execute_on_connection
[2024-08-11T05:28:00.640+0000] {subprocess.py:93} INFO -     return connection._execute_clauseelement(
[2024-08-11T05:28:00.640+0000] {subprocess.py:93} INFO -            ^^^^^^^^^^^^^^^^^^^^^^^^^^^^^^^^^^
[2024-08-11T05:28:00.640+0000] {subprocess.py:93} INFO -   File "/home/***/.local/lib/python3.12/site-packages/sqlalchemy/engine/base.py", line 1577, in _execute_clauseelement
[2024-08-11T05:28:00.640+0000] {subprocess.py:93} INFO -     ret = self._execute_context(
[2024-08-11T05:28:00.640+0000] {subprocess.py:93} INFO -           ^^^^^^^^^^^^^^^^^^^^^^
[2024-08-11T05:28:00.640+0000] {subprocess.py:93} INFO -   File "/home/***/.local/lib/python3.12/site-packages/sqlalchemy/engine/base.py", line 1953, in _execute_context
[2024-08-11T05:28:00.641+0000] {subprocess.py:93} INFO -     self._handle_dbapi_exception(
[2024-08-11T05:28:00.641+0000] {subprocess.py:93} INFO -   File "/home/***/.local/lib/python3.12/site-packages/sqlalchemy/engine/base.py", line 2134, in _handle_dbapi_exception
[2024-08-11T05:28:00.641+0000] {subprocess.py:93} INFO -     util.raise_(
[2024-08-11T05:28:00.641+0000] {subprocess.py:93} INFO -   File "/home/***/.local/lib/python3.12/site-packages/sqlalchemy/util/compat.py", line 211, in raise_
[2024-08-11T05:28:00.642+0000] {subprocess.py:93} INFO -     raise exception
[2024-08-11T05:28:00.642+0000] {subprocess.py:93} INFO -   File "/home/***/.local/lib/python3.12/site-packages/sqlalchemy/engine/base.py", line 1910, in _execute_context
[2024-08-11T05:28:00.642+0000] {subprocess.py:93} INFO -     self.dialect.do_execute(
[2024-08-11T05:28:00.642+0000] {subprocess.py:93} INFO -   File "/home/***/.local/lib/python3.12/site-packages/sqlalchemy/engine/default.py", line 736, in do_execute
[2024-08-11T05:28:00.642+0000] {subprocess.py:93} INFO -     cursor.execute(statement, parameters)
[2024-08-11T05:28:00.642+0000] {subprocess.py:93} INFO - sqlalchemy.exc.ProgrammingError: (psycopg2.errors.SyntaxError) syntax error at or near "date"
[2024-08-11T05:28:00.642+0000] {subprocess.py:93} INFO - LINE 3:     date TIMESTAMP,
[2024-08-11T05:28:00.643+0000] {subprocess.py:93} INFO -             ^
[2024-08-11T05:28:00.643+0000] {subprocess.py:93} INFO - 
[2024-08-11T05:28:00.643+0000] {subprocess.py:93} INFO - [SQL: CREATE TABLE IF NOT EXISTS openmeteo (
[2024-08-11T05:28:00.643+0000] {subprocess.py:93} INFO -     key STRING PRIMARY KEY
[2024-08-11T05:28:00.643+0000] {subprocess.py:93} INFO -     date TIMESTAMP,
[2024-08-11T05:28:00.643+0000] {subprocess.py:93} INFO -     temperature_2m DECIMAL,
[2024-08-11T05:28:00.643+0000] {subprocess.py:93} INFO -     relative_humidity_2m INT,
[2024-08-11T05:28:00.644+0000] {subprocess.py:93} INFO -     dew_point_2m DECIMAL,
[2024-08-11T05:28:00.644+0000] {subprocess.py:93} INFO -     apparent_temperature DECIMAL,
[2024-08-11T05:28:00.644+0000] {subprocess.py:93} INFO -     precipitation_probability DECIMAL,
[2024-08-11T05:28:00.644+0000] {subprocess.py:93} INFO -     precipitation DECIMAL,
[2024-08-11T05:28:00.644+0000] {subprocess.py:93} INFO -     rain DECIMAL,
[2024-08-11T05:28:00.644+0000] {subprocess.py:93} INFO -     snow DECIMAL,
[2024-08-11T05:28:00.644+0000] {subprocess.py:93} INFO -     cloud_cover INT,
[2024-08-11T05:28:00.645+0000] {subprocess.py:93} INFO -     visibility INT,
[2024-08-11T05:28:00.645+0000] {subprocess.py:93} INFO -     wind_speed_10m DECIMAL,
[2024-08-11T05:28:00.645+0000] {subprocess.py:93} INFO -     wind_direction_10m DECIMAL,
[2024-08-11T05:28:00.645+0000] {subprocess.py:93} INFO -     uv_index DECIMAL,
[2024-08-11T05:28:00.645+0000] {subprocess.py:93} INFO -     uv_index_clear_sky DECIMAL,
[2024-08-11T05:28:00.645+0000] {subprocess.py:93} INFO -     is_day INT
[2024-08-11T05:28:00.646+0000] {subprocess.py:93} INFO -     location STRING )]
[2024-08-11T05:28:00.646+0000] {subprocess.py:93} INFO - (Background on this error at: https://sqlalche.me/e/14/f405)
[2024-08-11T05:28:00.672+0000] {subprocess.py:97} INFO - Command exited with return code 1
[2024-08-11T05:28:00.673+0000] {taskinstance.py:441} INFO - ::group::Post task execution logs
[2024-08-11T05:28:00.688+0000] {taskinstance.py:2905} ERROR - Task failed with exception
Traceback (most recent call last):
  File "/home/airflow/.local/lib/python3.12/site-packages/airflow/models/taskinstance.py", line 465, in _execute_task
    result = _execute_callable(context=context, **execute_callable_kwargs)
             ^^^^^^^^^^^^^^^^^^^^^^^^^^^^^^^^^^^^^^^^^^^^^^^^^^^^^^^^^^^^^
  File "/home/airflow/.local/lib/python3.12/site-packages/airflow/models/taskinstance.py", line 432, in _execute_callable
    return execute_callable(context=context, **execute_callable_kwargs)
           ^^^^^^^^^^^^^^^^^^^^^^^^^^^^^^^^^^^^^^^^^^^^^^^^^^^^^^^^^^^^
  File "/home/airflow/.local/lib/python3.12/site-packages/airflow/models/baseoperator.py", line 401, in wrapper
    return func(self, *args, **kwargs)
           ^^^^^^^^^^^^^^^^^^^^^^^^^^^
  File "/home/airflow/.local/lib/python3.12/site-packages/airflow/operators/bash.py", line 243, in execute
    raise AirflowException(
airflow.exceptions.AirflowException: Bash command failed. The command returned a non-zero exit code 1.
[2024-08-11T05:28:00.696+0000] {taskinstance.py:1206} INFO - Marking task as UP_FOR_RETRY. dag_id=weather_data_migration, task_id=weather_data_migration, run_id=manual__2024-08-11T05:27:57.613781+00:00, execution_date=20240811T052757, start_date=20240811T052759, end_date=20240811T052800
[2024-08-11T05:28:00.708+0000] {standard_task_runner.py:110} ERROR - Failed to execute job 13 for task weather_data_migration (Bash command failed. The command returned a non-zero exit code 1.; 2795)
[2024-08-11T05:28:00.723+0000] {local_task_job_runner.py:243} INFO - Task exited with return code 1
[2024-08-11T05:28:00.752+0000] {taskinstance.py:3503} INFO - 0 downstream tasks scheduled from follow-on schedule check
[2024-08-11T05:28:00.753+0000] {local_task_job_runner.py:222} INFO - ::endgroup::
