[2024-08-11T05:18:17.726+0000] {local_task_job_runner.py:120} INFO - ::group::Pre task execution logs
[2024-08-11T05:18:17.736+0000] {taskinstance.py:2076} INFO - Dependencies all met for dep_context=non-requeueable deps ti=<TaskInstance: weather_data_migration.weather_data_migration manual__2024-08-11T05:17:13.399097+00:00 [queued]>
[2024-08-11T05:18:17.739+0000] {taskinstance.py:2076} INFO - Dependencies all met for dep_context=requeueable deps ti=<TaskInstance: weather_data_migration.weather_data_migration manual__2024-08-11T05:17:13.399097+00:00 [queued]>
[2024-08-11T05:18:17.739+0000] {taskinstance.py:2306} INFO - Starting attempt 2 of 2
[2024-08-11T05:18:17.743+0000] {taskinstance.py:2330} INFO - Executing <Task(BashOperator): weather_data_migration> on 2024-08-11 05:17:13.399097+00:00
[2024-08-11T05:18:17.747+0000] {warnings.py:112} WARNING - /home/***/.local/lib/python3.12/site-packages/***/task/task_runner/standard_task_runner.py:62: DeprecationWarning: This process (pid=2650) is multi-threaded, use of fork() may lead to deadlocks in the child.
  pid = os.fork()

[2024-08-11T05:18:17.748+0000] {standard_task_runner.py:64} INFO - Started process 2652 to run task
[2024-08-11T05:18:17.748+0000] {standard_task_runner.py:90} INFO - Running: ['***', 'tasks', 'run', 'weather_data_migration', 'weather_data_migration', 'manual__2024-08-11T05:17:13.399097+00:00', '--job-id', '10', '--raw', '--subdir', 'DAGS_FOLDER/weather_data_migration_dag.py', '--cfg-path', '/tmp/tmpjufpfsy6']
[2024-08-11T05:18:17.749+0000] {standard_task_runner.py:91} INFO - Job 10: Subtask weather_data_migration
[2024-08-11T05:18:17.768+0000] {task_command.py:426} INFO - Running <TaskInstance: weather_data_migration.weather_data_migration manual__2024-08-11T05:17:13.399097+00:00 [running]> on host a904838c11ba
[2024-08-11T05:18:17.796+0000] {taskinstance.py:2648} INFO - Exporting env vars: AIRFLOW_CTX_DAG_OWNER='***' AIRFLOW_CTX_DAG_ID='weather_data_migration' AIRFLOW_CTX_TASK_ID='weather_data_migration' AIRFLOW_CTX_EXECUTION_DATE='2024-08-11T05:17:13.399097+00:00' AIRFLOW_CTX_TRY_NUMBER='2' AIRFLOW_CTX_DAG_RUN_ID='manual__2024-08-11T05:17:13.399097+00:00'
[2024-08-11T05:18:17.797+0000] {taskinstance.py:430} INFO - ::endgroup::
[2024-08-11T05:18:17.798+0000] {subprocess.py:63} INFO - Tmp dir root location: /tmp
[2024-08-11T05:18:17.798+0000] {subprocess.py:75} INFO - Running command: ['/usr/bin/bash', '-c', 'python /opt/***/dags/weather_data_migration.py --connection postgresql+psycopg2://***:***@postgres/***']
[2024-08-11T05:18:17.802+0000] {subprocess.py:86} INFO - Output:
[2024-08-11T05:18:18.806+0000] {subprocess.py:93} INFO - Traceback (most recent call last):
[2024-08-11T05:18:18.807+0000] {subprocess.py:93} INFO -   File "/opt/***/dags/weather_data_migration.py", line 39, in <module>
[2024-08-11T05:18:18.807+0000] {subprocess.py:93} INFO -     main(args.connection)
[2024-08-11T05:18:18.807+0000] {subprocess.py:93} INFO -   File "/opt/***/dags/weather_data_migration.py", line 12, in main
[2024-08-11T05:18:18.807+0000] {subprocess.py:93} INFO -     session = connection.get_session()
[2024-08-11T05:18:18.807+0000] {subprocess.py:93} INFO -               ^^^^^^^^^^^^^^^^^^^^^^
[2024-08-11T05:18:18.808+0000] {subprocess.py:93} INFO - AttributeError: 'Connection' object has no attribute 'get_session'
[2024-08-11T05:18:18.919+0000] {subprocess.py:97} INFO - Command exited with return code 1
[2024-08-11T05:18:18.920+0000] {taskinstance.py:441} INFO - ::group::Post task execution logs
[2024-08-11T05:18:18.930+0000] {taskinstance.py:2905} ERROR - Task failed with exception
Traceback (most recent call last):
  File "/home/airflow/.local/lib/python3.12/site-packages/airflow/models/taskinstance.py", line 465, in _execute_task
    result = _execute_callable(context=context, **execute_callable_kwargs)
             ^^^^^^^^^^^^^^^^^^^^^^^^^^^^^^^^^^^^^^^^^^^^^^^^^^^^^^^^^^^^^
  File "/home/airflow/.local/lib/python3.12/site-packages/airflow/models/taskinstance.py", line 432, in _execute_callable
    return execute_callable(context=context, **execute_callable_kwargs)
           ^^^^^^^^^^^^^^^^^^^^^^^^^^^^^^^^^^^^^^^^^^^^^^^^^^^^^^^^^^^^
  File "/home/airflow/.local/lib/python3.12/site-packages/airflow/models/baseoperator.py", line 401, in wrapper
    return func(self, *args, **kwargs)
           ^^^^^^^^^^^^^^^^^^^^^^^^^^^
  File "/home/airflow/.local/lib/python3.12/site-packages/airflow/operators/bash.py", line 243, in execute
    raise AirflowException(
airflow.exceptions.AirflowException: Bash command failed. The command returned a non-zero exit code 1.
[2024-08-11T05:18:18.936+0000] {taskinstance.py:1206} INFO - Marking task as FAILED. dag_id=weather_data_migration, task_id=weather_data_migration, run_id=manual__2024-08-11T05:17:13.399097+00:00, execution_date=20240811T051713, start_date=20240811T051817, end_date=20240811T051818
[2024-08-11T05:18:18.945+0000] {standard_task_runner.py:110} ERROR - Failed to execute job 10 for task weather_data_migration (Bash command failed. The command returned a non-zero exit code 1.; 2652)
[2024-08-11T05:18:18.983+0000] {local_task_job_runner.py:243} INFO - Task exited with return code 1
[2024-08-11T05:18:18.993+0000] {taskinstance.py:3503} INFO - 0 downstream tasks scheduled from follow-on schedule check
[2024-08-11T05:18:18.995+0000] {local_task_job_runner.py:222} INFO - ::endgroup::
