[2024-08-11T20:56:58.821+0000] {local_task_job_runner.py:120} INFO - ::group::Pre task execution logs
[2024-08-11T20:56:58.831+0000] {taskinstance.py:2076} INFO - Dependencies all met for dep_context=non-requeueable deps ti=<TaskInstance: weather_data_table_drop.weather_data_table_drop scheduled__2024-08-01T00:00:00+00:00 [queued]>
[2024-08-11T20:56:58.834+0000] {taskinstance.py:2076} INFO - Dependencies all met for dep_context=requeueable deps ti=<TaskInstance: weather_data_table_drop.weather_data_table_drop scheduled__2024-08-01T00:00:00+00:00 [queued]>
[2024-08-11T20:56:58.834+0000] {taskinstance.py:2306} INFO - Starting attempt 2 of 2
[2024-08-11T20:56:58.839+0000] {taskinstance.py:2330} INFO - Executing <Task(BashOperator): weather_data_table_drop> on 2024-08-01 00:00:00+00:00
[2024-08-11T20:56:58.842+0000] {warnings.py:112} WARNING - /home/***/.local/lib/python3.12/site-packages/***/task/task_runner/standard_task_runner.py:62: DeprecationWarning: This process (pid=189) is multi-threaded, use of fork() may lead to deadlocks in the child.
  pid = os.fork()

[2024-08-11T20:56:58.843+0000] {standard_task_runner.py:64} INFO - Started process 191 to run task
[2024-08-11T20:56:58.844+0000] {standard_task_runner.py:90} INFO - Running: ['***', 'tasks', 'run', 'weather_data_table_drop', 'weather_data_table_drop', 'scheduled__2024-08-01T00:00:00+00:00', '--job-id', '99', '--raw', '--subdir', 'DAGS_FOLDER/delete_openmeteo_dag.py', '--cfg-path', '/tmp/tmpc2hnmsw1']
[2024-08-11T20:56:58.845+0000] {standard_task_runner.py:91} INFO - Job 99: Subtask weather_data_table_drop
[2024-08-11T20:56:58.872+0000] {task_command.py:426} INFO - Running <TaskInstance: weather_data_table_drop.weather_data_table_drop scheduled__2024-08-01T00:00:00+00:00 [running]> on host 14d759344545
[2024-08-11T20:56:58.914+0000] {taskinstance.py:2648} INFO - Exporting env vars: AIRFLOW_CTX_DAG_OWNER='***' AIRFLOW_CTX_DAG_ID='weather_data_table_drop' AIRFLOW_CTX_TASK_ID='weather_data_table_drop' AIRFLOW_CTX_EXECUTION_DATE='2024-08-01T00:00:00+00:00' AIRFLOW_CTX_TRY_NUMBER='2' AIRFLOW_CTX_DAG_RUN_ID='scheduled__2024-08-01T00:00:00+00:00'
[2024-08-11T20:56:58.915+0000] {taskinstance.py:430} INFO - ::endgroup::
[2024-08-11T20:56:58.916+0000] {subprocess.py:63} INFO - Tmp dir root location: /tmp
[2024-08-11T20:56:58.917+0000] {subprocess.py:75} INFO - Running command: ['/usr/bin/bash', '-c', 'python /opt/***/dags/delete_table.py --connection postgresql+psycopg2://***:***@postgres/***']
[2024-08-11T20:56:58.921+0000] {subprocess.py:86} INFO - Output:
[2024-08-11T20:56:59.308+0000] {subprocess.py:93} INFO - Traceback (most recent call last):
[2024-08-11T20:56:59.309+0000] {subprocess.py:93} INFO -   File "/home/***/.local/lib/python3.12/site-packages/sqlalchemy/engine/base.py", line 1910, in _execute_context
[2024-08-11T20:56:59.309+0000] {subprocess.py:93} INFO -     self.dialect.do_execute(
[2024-08-11T20:56:59.309+0000] {subprocess.py:93} INFO -   File "/home/***/.local/lib/python3.12/site-packages/sqlalchemy/engine/default.py", line 736, in do_execute
[2024-08-11T20:56:59.309+0000] {subprocess.py:93} INFO -     cursor.execute(statement, parameters)
[2024-08-11T20:56:59.310+0000] {subprocess.py:93} INFO - psycopg2.errors.UndefinedTable: table "openmeteo" does not exist
[2024-08-11T20:56:59.310+0000] {subprocess.py:93} INFO - 
[2024-08-11T20:56:59.310+0000] {subprocess.py:93} INFO - 
[2024-08-11T20:56:59.310+0000] {subprocess.py:93} INFO - The above exception was the direct cause of the following exception:
[2024-08-11T20:56:59.310+0000] {subprocess.py:93} INFO - 
[2024-08-11T20:56:59.310+0000] {subprocess.py:93} INFO - Traceback (most recent call last):
[2024-08-11T20:56:59.310+0000] {subprocess.py:93} INFO -   File "/opt/***/dags/delete_table.py", line 21, in <module>
[2024-08-11T20:56:59.310+0000] {subprocess.py:93} INFO -     main(args.connection)
[2024-08-11T20:56:59.310+0000] {subprocess.py:93} INFO -   File "/opt/***/dags/delete_table.py", line 13, in main
[2024-08-11T20:56:59.311+0000] {subprocess.py:93} INFO -     session.execute('''DROP TABLE openmeteo''')
[2024-08-11T20:56:59.311+0000] {subprocess.py:93} INFO -   File "/home/***/.local/lib/python3.12/site-packages/sqlalchemy/orm/session.py", line 1717, in execute
[2024-08-11T20:56:59.311+0000] {subprocess.py:93} INFO -     result = conn._execute_20(statement, params or {}, execution_options)
[2024-08-11T20:56:59.311+0000] {subprocess.py:93} INFO -              ^^^^^^^^^^^^^^^^^^^^^^^^^^^^^^^^^^^^^^^^^^^^^^^^^^^^^^^^^^^^
[2024-08-11T20:56:59.311+0000] {subprocess.py:93} INFO -   File "/home/***/.local/lib/python3.12/site-packages/sqlalchemy/engine/base.py", line 1710, in _execute_20
[2024-08-11T20:56:59.311+0000] {subprocess.py:93} INFO -     return meth(self, args_10style, kwargs_10style, execution_options)
[2024-08-11T20:56:59.311+0000] {subprocess.py:93} INFO -            ^^^^^^^^^^^^^^^^^^^^^^^^^^^^^^^^^^^^^^^^^^^^^^^^^^^^^^^^^^^
[2024-08-11T20:56:59.311+0000] {subprocess.py:93} INFO -   File "/home/***/.local/lib/python3.12/site-packages/sqlalchemy/sql/elements.py", line 334, in _execute_on_connection
[2024-08-11T20:56:59.311+0000] {subprocess.py:93} INFO -     return connection._execute_clauseelement(
[2024-08-11T20:56:59.311+0000] {subprocess.py:93} INFO -            ^^^^^^^^^^^^^^^^^^^^^^^^^^^^^^^^^^
[2024-08-11T20:56:59.311+0000] {subprocess.py:93} INFO -   File "/home/***/.local/lib/python3.12/site-packages/sqlalchemy/engine/base.py", line 1577, in _execute_clauseelement
[2024-08-11T20:56:59.312+0000] {subprocess.py:93} INFO -     ret = self._execute_context(
[2024-08-11T20:56:59.312+0000] {subprocess.py:93} INFO -           ^^^^^^^^^^^^^^^^^^^^^^
[2024-08-11T20:56:59.312+0000] {subprocess.py:93} INFO -   File "/home/***/.local/lib/python3.12/site-packages/sqlalchemy/engine/base.py", line 1953, in _execute_context
[2024-08-11T20:56:59.312+0000] {subprocess.py:93} INFO -     self._handle_dbapi_exception(
[2024-08-11T20:56:59.312+0000] {subprocess.py:93} INFO -   File "/home/***/.local/lib/python3.12/site-packages/sqlalchemy/engine/base.py", line 2134, in _handle_dbapi_exception
[2024-08-11T20:56:59.312+0000] {subprocess.py:93} INFO -     util.raise_(
[2024-08-11T20:56:59.312+0000] {subprocess.py:93} INFO -   File "/home/***/.local/lib/python3.12/site-packages/sqlalchemy/util/compat.py", line 211, in raise_
[2024-08-11T20:56:59.312+0000] {subprocess.py:93} INFO -     raise exception
[2024-08-11T20:56:59.312+0000] {subprocess.py:93} INFO -   File "/home/***/.local/lib/python3.12/site-packages/sqlalchemy/engine/base.py", line 1910, in _execute_context
[2024-08-11T20:56:59.312+0000] {subprocess.py:93} INFO -     self.dialect.do_execute(
[2024-08-11T20:56:59.312+0000] {subprocess.py:93} INFO -   File "/home/***/.local/lib/python3.12/site-packages/sqlalchemy/engine/default.py", line 736, in do_execute
[2024-08-11T20:56:59.312+0000] {subprocess.py:93} INFO -     cursor.execute(statement, parameters)
[2024-08-11T20:56:59.313+0000] {subprocess.py:93} INFO - sqlalchemy.exc.ProgrammingError: (psycopg2.errors.UndefinedTable) table "openmeteo" does not exist
[2024-08-11T20:56:59.313+0000] {subprocess.py:93} INFO - 
[2024-08-11T20:56:59.313+0000] {subprocess.py:93} INFO - [SQL: DROP TABLE openmeteo]
[2024-08-11T20:56:59.313+0000] {subprocess.py:93} INFO - (Background on this error at: https://sqlalche.me/e/14/f405)
[2024-08-11T20:56:59.341+0000] {subprocess.py:97} INFO - Command exited with return code 1
[2024-08-11T20:56:59.342+0000] {taskinstance.py:441} INFO - ::group::Post task execution logs
[2024-08-11T20:56:59.350+0000] {taskinstance.py:2905} ERROR - Task failed with exception
Traceback (most recent call last):
  File "/home/airflow/.local/lib/python3.12/site-packages/airflow/models/taskinstance.py", line 465, in _execute_task
    result = _execute_callable(context=context, **execute_callable_kwargs)
             ^^^^^^^^^^^^^^^^^^^^^^^^^^^^^^^^^^^^^^^^^^^^^^^^^^^^^^^^^^^^^
  File "/home/airflow/.local/lib/python3.12/site-packages/airflow/models/taskinstance.py", line 432, in _execute_callable
    return execute_callable(context=context, **execute_callable_kwargs)
           ^^^^^^^^^^^^^^^^^^^^^^^^^^^^^^^^^^^^^^^^^^^^^^^^^^^^^^^^^^^^
  File "/home/airflow/.local/lib/python3.12/site-packages/airflow/models/baseoperator.py", line 401, in wrapper
    return func(self, *args, **kwargs)
           ^^^^^^^^^^^^^^^^^^^^^^^^^^^
  File "/home/airflow/.local/lib/python3.12/site-packages/airflow/operators/bash.py", line 243, in execute
    raise AirflowException(
airflow.exceptions.AirflowException: Bash command failed. The command returned a non-zero exit code 1.
[2024-08-11T20:56:59.355+0000] {taskinstance.py:1206} INFO - Marking task as FAILED. dag_id=weather_data_table_drop, task_id=weather_data_table_drop, run_id=scheduled__2024-08-01T00:00:00+00:00, execution_date=20240801T000000, start_date=20240811T205658, end_date=20240811T205659
[2024-08-11T20:56:59.361+0000] {standard_task_runner.py:110} ERROR - Failed to execute job 99 for task weather_data_table_drop (Bash command failed. The command returned a non-zero exit code 1.; 191)
[2024-08-11T20:56:59.411+0000] {local_task_job_runner.py:243} INFO - Task exited with return code 1
[2024-08-11T20:56:59.420+0000] {taskinstance.py:3503} INFO - 0 downstream tasks scheduled from follow-on schedule check
[2024-08-11T20:56:59.420+0000] {local_task_job_runner.py:222} INFO - ::endgroup::
