[2024-08-11T20:29:43.512+0000] {local_task_job_runner.py:120} INFO - ::group::Pre task execution logs
[2024-08-11T20:29:43.522+0000] {taskinstance.py:2076} INFO - Dependencies all met for dep_context=non-requeueable deps ti=<TaskInstance: weather.export_data_to_db manual__2024-08-11T20:29:38.499490+00:00 [queued]>
[2024-08-11T20:29:43.524+0000] {taskinstance.py:2076} INFO - Dependencies all met for dep_context=requeueable deps ti=<TaskInstance: weather.export_data_to_db manual__2024-08-11T20:29:38.499490+00:00 [queued]>
[2024-08-11T20:29:43.525+0000] {taskinstance.py:2306} INFO - Starting attempt 1 of 2
[2024-08-11T20:29:43.529+0000] {taskinstance.py:2330} INFO - Executing <Task(BashOperator): export_data_to_db> on 2024-08-11 20:29:38.499490+00:00
[2024-08-11T20:29:43.532+0000] {warnings.py:112} WARNING - /home/***/.local/lib/python3.12/site-packages/***/task/task_runner/standard_task_runner.py:62: DeprecationWarning: This process (pid=484) is multi-threaded, use of fork() may lead to deadlocks in the child.
  pid = os.fork()

[2024-08-11T20:29:43.533+0000] {standard_task_runner.py:64} INFO - Started process 486 to run task
[2024-08-11T20:29:43.533+0000] {standard_task_runner.py:90} INFO - Running: ['***', 'tasks', 'run', 'weather', 'export_data_to_db', 'manual__2024-08-11T20:29:38.499490+00:00', '--job-id', '67', '--raw', '--subdir', 'DAGS_FOLDER/weather_dag.py', '--cfg-path', '/tmp/tmpjnt2en5s']
[2024-08-11T20:29:43.534+0000] {standard_task_runner.py:91} INFO - Job 67: Subtask export_data_to_db
[2024-08-11T20:29:43.551+0000] {task_command.py:426} INFO - Running <TaskInstance: weather.export_data_to_db manual__2024-08-11T20:29:38.499490+00:00 [running]> on host 032430a33e2d
[2024-08-11T20:29:43.581+0000] {taskinstance.py:2648} INFO - Exporting env vars: AIRFLOW_CTX_DAG_OWNER='***' AIRFLOW_CTX_DAG_ID='weather' AIRFLOW_CTX_TASK_ID='export_data_to_db' AIRFLOW_CTX_EXECUTION_DATE='2024-08-11T20:29:38.499490+00:00' AIRFLOW_CTX_TRY_NUMBER='1' AIRFLOW_CTX_DAG_RUN_ID='manual__2024-08-11T20:29:38.499490+00:00'
[2024-08-11T20:29:43.582+0000] {taskinstance.py:430} INFO - ::endgroup::
[2024-08-11T20:29:43.582+0000] {subprocess.py:63} INFO - Tmp dir root location: /tmp
[2024-08-11T20:29:43.582+0000] {subprocess.py:75} INFO - Running command: ['/usr/bin/bash', '-c', 'python /opt/***/dags/weather_to_db.py --date 2024-08-11 --connection postgresql+psycopg2://***:***@postgres/***']
[2024-08-11T20:29:43.587+0000] {subprocess.py:86} INFO - Output:
[2024-08-11T20:29:43.929+0000] {subprocess.py:93} INFO - Traceback (most recent call last):
[2024-08-11T20:29:43.930+0000] {subprocess.py:93} INFO -   File "/opt/***/dags/weather_to_db.py", line 59, in <module>
[2024-08-11T20:29:43.930+0000] {subprocess.py:93} INFO -     main(args.date, args.connection)
[2024-08-11T20:29:43.930+0000] {subprocess.py:93} INFO -   File "/opt/***/dags/weather_to_db.py", line 36, in main
[2024-08-11T20:29:43.930+0000] {subprocess.py:93} INFO -     snowfall = row['snow'],
[2024-08-11T20:29:43.931+0000] {subprocess.py:93} INFO -                ~~~^^^^^^^^
[2024-08-11T20:29:43.931+0000] {subprocess.py:93} INFO - KeyError: 'snow'
[2024-08-11T20:29:43.952+0000] {subprocess.py:97} INFO - Command exited with return code 1
[2024-08-11T20:29:43.953+0000] {taskinstance.py:441} INFO - ::group::Post task execution logs
[2024-08-11T20:29:43.957+0000] {taskinstance.py:2905} ERROR - Task failed with exception
Traceback (most recent call last):
  File "/home/airflow/.local/lib/python3.12/site-packages/airflow/models/taskinstance.py", line 465, in _execute_task
    result = _execute_callable(context=context, **execute_callable_kwargs)
             ^^^^^^^^^^^^^^^^^^^^^^^^^^^^^^^^^^^^^^^^^^^^^^^^^^^^^^^^^^^^^
  File "/home/airflow/.local/lib/python3.12/site-packages/airflow/models/taskinstance.py", line 432, in _execute_callable
    return execute_callable(context=context, **execute_callable_kwargs)
           ^^^^^^^^^^^^^^^^^^^^^^^^^^^^^^^^^^^^^^^^^^^^^^^^^^^^^^^^^^^^
  File "/home/airflow/.local/lib/python3.12/site-packages/airflow/models/baseoperator.py", line 401, in wrapper
    return func(self, *args, **kwargs)
           ^^^^^^^^^^^^^^^^^^^^^^^^^^^
  File "/home/airflow/.local/lib/python3.12/site-packages/airflow/operators/bash.py", line 243, in execute
    raise AirflowException(
airflow.exceptions.AirflowException: Bash command failed. The command returned a non-zero exit code 1.
[2024-08-11T20:29:43.960+0000] {taskinstance.py:1206} INFO - Marking task as UP_FOR_RETRY. dag_id=weather, task_id=export_data_to_db, run_id=manual__2024-08-11T20:29:38.499490+00:00, execution_date=20240811T202938, start_date=20240811T202943, end_date=20240811T202943
[2024-08-11T20:29:43.966+0000] {standard_task_runner.py:110} ERROR - Failed to execute job 67 for task export_data_to_db (Bash command failed. The command returned a non-zero exit code 1.; 486)
[2024-08-11T20:29:43.972+0000] {local_task_job_runner.py:243} INFO - Task exited with return code 1
[2024-08-11T20:29:43.980+0000] {taskinstance.py:3503} INFO - 0 downstream tasks scheduled from follow-on schedule check
[2024-08-11T20:29:43.981+0000] {local_task_job_runner.py:222} INFO - ::endgroup::
