[2024-08-11T20:06:33.529+0000] {local_task_job_runner.py:120} INFO - ::group::Pre task execution logs
[2024-08-11T20:06:33.542+0000] {taskinstance.py:2076} INFO - Dependencies all met for dep_context=non-requeueable deps ti=<TaskInstance: weather.export_data_to_db manual__2024-08-11T20:06:24.952194+00:00 [queued]>
[2024-08-11T20:06:33.546+0000] {taskinstance.py:2076} INFO - Dependencies all met for dep_context=requeueable deps ti=<TaskInstance: weather.export_data_to_db manual__2024-08-11T20:06:24.952194+00:00 [queued]>
[2024-08-11T20:06:33.546+0000] {taskinstance.py:2306} INFO - Starting attempt 1 of 2
[2024-08-11T20:06:33.551+0000] {taskinstance.py:2330} INFO - Executing <Task(BashOperator): export_data_to_db> on 2024-08-11 20:06:24.952194+00:00
[2024-08-11T20:06:33.556+0000] {warnings.py:112} WARNING - /home/***/.local/lib/python3.12/site-packages/***/task/task_runner/standard_task_runner.py:62: DeprecationWarning: This process (pid=106) is multi-threaded, use of fork() may lead to deadlocks in the child.
  pid = os.fork()

[2024-08-11T20:06:33.558+0000] {standard_task_runner.py:64} INFO - Started process 108 to run task
[2024-08-11T20:06:33.558+0000] {standard_task_runner.py:90} INFO - Running: ['***', 'tasks', 'run', 'weather', 'export_data_to_db', 'manual__2024-08-11T20:06:24.952194+00:00', '--job-id', '55', '--raw', '--subdir', 'DAGS_FOLDER/weather_dag.py', '--cfg-path', '/tmp/tmpfglawxs_']
[2024-08-11T20:06:33.561+0000] {standard_task_runner.py:91} INFO - Job 55: Subtask export_data_to_db
[2024-08-11T20:06:33.583+0000] {task_command.py:426} INFO - Running <TaskInstance: weather.export_data_to_db manual__2024-08-11T20:06:24.952194+00:00 [running]> on host 032430a33e2d
[2024-08-11T20:06:33.614+0000] {taskinstance.py:2648} INFO - Exporting env vars: AIRFLOW_CTX_DAG_OWNER='***' AIRFLOW_CTX_DAG_ID='weather' AIRFLOW_CTX_TASK_ID='export_data_to_db' AIRFLOW_CTX_EXECUTION_DATE='2024-08-11T20:06:24.952194+00:00' AIRFLOW_CTX_TRY_NUMBER='1' AIRFLOW_CTX_DAG_RUN_ID='manual__2024-08-11T20:06:24.952194+00:00'
[2024-08-11T20:06:33.615+0000] {taskinstance.py:430} INFO - ::endgroup::
[2024-08-11T20:06:33.615+0000] {subprocess.py:63} INFO - Tmp dir root location: /tmp
[2024-08-11T20:06:33.616+0000] {subprocess.py:75} INFO - Running command: ['/usr/bin/bash', '-c', 'python /opt/***/dags/weather_to_db.py --date 2024-08-11 --connection postgresql+psycopg2://***:***@postgres/***']
[2024-08-11T20:06:33.620+0000] {subprocess.py:86} INFO - Output:
[2024-08-11T20:06:33.655+0000] {subprocess.py:93} INFO - python: can't open file '/opt/***/dags/weather_to_db.py': [Errno 2] No such file or directory
[2024-08-11T20:06:33.657+0000] {subprocess.py:97} INFO - Command exited with return code 2
[2024-08-11T20:06:33.657+0000] {taskinstance.py:441} INFO - ::group::Post task execution logs
[2024-08-11T20:06:33.661+0000] {taskinstance.py:2905} ERROR - Task failed with exception
Traceback (most recent call last):
  File "/home/airflow/.local/lib/python3.12/site-packages/airflow/models/taskinstance.py", line 465, in _execute_task
    result = _execute_callable(context=context, **execute_callable_kwargs)
             ^^^^^^^^^^^^^^^^^^^^^^^^^^^^^^^^^^^^^^^^^^^^^^^^^^^^^^^^^^^^^
  File "/home/airflow/.local/lib/python3.12/site-packages/airflow/models/taskinstance.py", line 432, in _execute_callable
    return execute_callable(context=context, **execute_callable_kwargs)
           ^^^^^^^^^^^^^^^^^^^^^^^^^^^^^^^^^^^^^^^^^^^^^^^^^^^^^^^^^^^^
  File "/home/airflow/.local/lib/python3.12/site-packages/airflow/models/baseoperator.py", line 401, in wrapper
    return func(self, *args, **kwargs)
           ^^^^^^^^^^^^^^^^^^^^^^^^^^^
  File "/home/airflow/.local/lib/python3.12/site-packages/airflow/operators/bash.py", line 243, in execute
    raise AirflowException(
airflow.exceptions.AirflowException: Bash command failed. The command returned a non-zero exit code 2.
[2024-08-11T20:06:33.667+0000] {taskinstance.py:1206} INFO - Marking task as UP_FOR_RETRY. dag_id=weather, task_id=export_data_to_db, run_id=manual__2024-08-11T20:06:24.952194+00:00, execution_date=20240811T200624, start_date=20240811T200633, end_date=20240811T200633
[2024-08-11T20:06:33.672+0000] {standard_task_runner.py:110} ERROR - Failed to execute job 55 for task export_data_to_db (Bash command failed. The command returned a non-zero exit code 2.; 108)
[2024-08-11T20:06:33.701+0000] {local_task_job_runner.py:243} INFO - Task exited with return code 1
[2024-08-11T20:06:33.707+0000] {taskinstance.py:3503} INFO - 0 downstream tasks scheduled from follow-on schedule check
[2024-08-11T20:06:33.708+0000] {local_task_job_runner.py:222} INFO - ::endgroup::
